Workbook

Sheet Read Me
A1: OL-GA
A2: Features, functionality and user-flow specification
A3: Version 2 - reconciled against 'Story first, then the spec for your architect' (A week in Ol-ga) · 4 September 2026
A5: PURPOSE
C6: This workbook is the buildable specification for the Ol-ga MVP. It is written for the build team (1 senior + 2 junior React Native developers) and is intended to be worked from directly: every feature has an ID, an owner, an acceptance criterion, the screen states it needs and the analytics events it fires.
C7: It is derived from four documents and does not supersede them: the STORY BRIEF ('A week in Ol-ga'), the OL-GA MVP Build Plan (Sept 2026), the OL-GA Social Capital Liquidity Memo (July 2026), and the Ol-ga Six-Month Roadmap (Sept 2026).
C8: WHERE THE STORY AND THE BUILD PLAN DISAGREE, THE STORY WINS. Version 1 of this workbook was built from the build plan and had drifted from the story in eleven places. Every one is documented on the 'Story Alignment' tab, with the decision taken. Four of them were product decisions made by the founder on 4 Sept, not corrections.
A9: THE SCOPE BOUNDARY - read this before using the workbook
C10: The 'Feature Register' tab is the 12-week MVP. The 'Phase 2 Register' tab is NOT. It is specified at the same depth because you asked for it, but every Phase 2 item carries an explicit entry condition - a piece of evidence that must exist before work starts. Pulling any Phase 2 item forward without meeting its entry condition is how a 12-week build becomes an 18-week one.
C11: The scope-change protocol from the build plan applies to this workbook: any addition requires an equal-sized removal, in writing, signed by both sides. That applies to founder requests too - most late scope in fixed-date builds comes from the founder, not the contractor.
A13: HOW TO USE EACH TAB
A14: Story Alignment | C14: The cross-check of this workbook against the story brief 'A week in Ol-ga'. Every place v1 drifted, what changed, and who decided. Read this first if you knew version 1.
A15: Glossary | C15: The canonical vocabulary. Agree these words once, then use only these words - in the code, in the UI, in the analytics taxonomy and in investor materials. The 'What it is NOT' column is the useful half.
A16: Feature Register | C16: The 12-week MVP scope. Filter by Milestone to see what a payment gate contains, by Owner to see a lane, or by Priority to see the cut list.
A17: Phase 2 Register | C17: Post-MVP. Each row names the evidence required before starting. Do not start any of these inside the 12 weeks.
A18: User Journey | C18: The 34 numbered steps a real attendee goes through, end to end, including the steps where Ol-ga deliberately does nothing. Use it to check that no step has an undefined failure path.
A19: Screens & States | C19: Every screen with every state - default, empty, loading, error, offline, permission-denied. Definition of done for a screen includes ALL of its rows here, not just the default.
A20: Notifications | C20: Every notification with trigger, timing, copy and opt-out behaviour. The guardrail column says what each one can break.
A21: Analytics Events | C21: The event taxonomy. This is FROZEN at M0 and wired before the first feature screen. Do not add, rename or redefine an event after sign-off.
A22: Event Ops Runbook | C22: The 20 steps your team runs around an event, most of which are not engineering. Step 1 is the highest-ranked initiative in the whole roadmap.
A23: Not Building | C23: Tempting features that are deliberately out of scope, each with the specific evidence that would justify reconsidering it.
A24: Milestone Checklist | C24: The binary acceptance criteria for M0-M5 and the payment attached to each. A criterion is either met or it is not - there is no partial credit.
A26: LEGEND
A27: Priority P0 | C27: Must ship for the Brand Laureate event. Not cuttable.
A28: Priority P1 | C28: Ships if the build is on track. First to be cut at the Week 8 review.
A29: Priority P2 | C29: Convenience. Cut without discussion if behind.
A30: Effort XS / S / M / L | C30: Under 1 dev-day / 1-3 dev-days / 4-8 dev-days / 9+ dev-days.
A31: Owner SD / JA / JB / F | C31: Senior developer / Junior A / Junior B / Founder. SD is planned at 55% coding capacity - the rest is contracts, review and unblocking.
A32: Type | C32: Table stakes = expected of any app · Differentiating = why Ol-ga exists · Operational = the plumbing that makes the experiment measurable.
A33: Milestone M0-M5 | C33: Payment gates from the build plan. See the Milestone Checklist tab.
A35: WHY ALMOST EVERYTHING IS P0
C36: Almost every feature is P0 (see the live counts below), which normally signals a failure to prioritise. Here it is a consequence of the scope having already been cut to the bone in the roadmap: what remains is the seven-step loop plus the plumbing that makes it measurable and launchable, and removing any of it either breaks the loop or breaks the measurement. The prioritisation work happened on the 'Not Building' tab, not in this column.
C37: THE CUT LIST, in order, if the build is behind at the Week 8 review: (1) F-020 match set refresh, (2) F-004 LinkedIn prefill, (3) F-062 notification preferences, (4) admin-panel polish (F-073 reduced to a database console), (5) Android visual polish, (6) F-049 cross-event ledger continuity, (7) decay-indicator visual sophistication (keep the indicator, simplify the treatment). NEVER cut: F-045 Ledger, F-047 decay indicator, F-052/F-054 the outcome loop, F-079 the off-event flag. Those four are what the next raise rests on.
A39: SCOPE AT A GLANCE (live counts - these recalculate)
A40: MVP features specified | B40: =COUNTIF('Feature Register'!$A$2:$A$200,"F-*") -> 79
A41: of which P0 (must ship) | B41: =COUNTIF('Feature Register'!$H$2:$H$200,"P0") -> 72
A42: of which P1 | B42: =COUNTIF('Feature Register'!$H$2:$H$200,"P1") -> 6
A43: of which P2 | B43: =COUNTIF('Feature Register'!$H$2:$H$200,"P2") -> 1
A44: Due at M0 (end W1, 13 Sep) | B44: =COUNTIF('Feature Register'!$I$2:$I$200,"M0") -> 4
A45: Due at M1 (end W3, 27 Sep) | B45: =COUNTIF('Feature Register'!$I$2:$I$200,"M1") -> 12
...

Sheet Story Alignment
A1: Story beat | B1: What the story says | C1: Status | D1: What version 1 had | E1: What version 2 does | F1: Feature IDs | G1: Decision owner / date
A2: Ticket confirmation asks one question | B2: 'At the bottom, one question: what are you hoping to get out of the evening?' | C2: Already covered | D2: Deep link from the ticket confirmation landing on intent capture | E2: Unchanged | F2: F-002 | G2: -
A3: Onboarding is 40 seconds | B3: 'You tap through, verify your number, type your role, and write one line. Forty seconds.' | C3: CHANGED | D3: Name, photo, role, company - a ~90 second target | E3: Name and role only. Photo deferred to after the first Reveal. Company removed. | F3: F-003, F-008 | G3: Founder, 4 Sep
A4: One line, not a form | B4: 'write one line - looking for a distribution partner for our fintech product in Indonesia' | C4: CHANGED | D4: One free-text line PLUS two structured selects, per the MVP Build Plan | E4: One free-text line. The two selects are removed. The hard rules layer now derives its filters from role text and event type. | F4: F-010, F-014 | G4: Founder, 4 Sep
A5: Entry is opening the app | B5: 'You open Ol-ga and tap Go Live.' No mention of scanning anything. | C5: CHANGED | D5: Venue QR scan as the primary path, geofence as fallback | E5: Geofence is the primary path; QR is the backup and the only co-working path. Both remain P0. | F5: F-025, F-026 | G5: Founder, 4 Sep
A6: Three, not three hundred | B6: 'You don't get three hundred names. You get three.' | C6: Already covered | D6: Exactly three matches per Go Live | E6: Unchanged | F6: F-015 | G6: -
A7: The reason is written out | B7: 'The reason is written out. You can see exactly why she's on your screen.' | C7: Already covered | D7: LLM-generated grounded explanation, 25 words, entity-validated | E7: Unchanged | F7: F-016, F-017 | G7: -
A8: Near the north bar | B8: 'Regional director, payments. Also live, near the north bar.' | C8: WAS MISSING | D8: No in-venue location at all before Reveal; only a coarse cue after mutual accept | E8: A SELF-DECLARED venue zone, chosen by the user from an operator-configured list when going Live, shown on the Match Card pre-accept. Volunteered, never sensed - so no location is inferred or stored and the privacy invariant holds. | F8: F-021 | G8: Founder, 4 Sep
A9: She can see your reason too | B9: 'She accepts in ninety seconds because she can see your reason too.' | C9: Already covered | D9: Incoming request shows the requester's explanation without their identity | E9: Unchanged, plus the requester's zone | F9: F-036, F-037 | G9: -
A10: Ol-ga does not have the conversation | B10: 'Ol-ga does not have the conversation for you - that part is still your job.' | C10: Already covered | D10: No in-app chat, permanently. Journey step 20 is explicitly 'the product does nothing here'. | E10: Unchanged | F10: (by design, none) | G10: -
A11: Go live for the hour | B11: 'You go live for the hour before your meeting' | C11: WAS MISSING | D11: A system-imposed session TTL, with no user control over duration | E11: A user-chosen availability window on Go Live. Defaults to one hour or to event end, with time remaining visible. | F11: F-027 | G11: Founder, 4 Sep
A12: A different intent | B12: 'with a different intent: hiring a senior backend engineer' | C12: CHANGED | D12: Intent bound to an Event, editable at the venue | E12: Intent belongs to a Go Live SESSION. A new room pre-fills the last intent but explicitly prompts a rewrite. This is a data-model decision - settle it at M0. | F12: F-011 | G12: Founder, 4 Sep
... A22: Timing, Reason, Memory | B22: 'You got three things LinkedIn structurally cannot give you. Timing. Reason. And memory.' | C22: STRUCTURAL FINDING | D22: v1 covered Timing and Reason well. Memory was the weakest pillar - five of the seven gaps found in this review sat in the ledger and outcome loop. | E22: Memory is now specified to the same depth as the other two: own-words intent, commitment capture, usefulness labels, elapsed-time decay. This matters because the story names Memory as the reason people open the app on a Tuesday - which is exactly what week-4 off-event retention measures. | F22: F-045 to F-050, F-052 to F-056 | G22: -

Sheet Glossary
A1: Term (internal) | B1: User-facing label | C1: Definition | D1: What it is NOT | E1: Where it appears | F1: Related terms
A2: Ol-ga | B2: Ol-ga | C2: The product. A mobile app that makes professional availability visible and actionable inside a physical space, for the duration of that space. | D2: Not a social network, not a messaging app, not an event app. It has no feed and no chat. | E2: Everywhere | F2: Live Room, Ledger
A3: Event | B3: Event | C3: A time-boxed gathering created by an operator in the admin panel, with a venue, a start/end window and a QR secret. All matching is scoped to one Event. | D3: Not a calendar entry the user creates. Users never create Events in the MVP. | E3: Admin panel; Live Room | F3: Venue Session, Live Room, Organiser
A4: Organiser | B4: Organiser | C4: The company or person running the Event and, from Phase 6, the paying customer. Brand Laureate is Organiser #1. | D4: Not a user role inside the app in the MVP - Organisers are served by your team, by hand. | E4: Commercial docs; Outcome Report | F4: Event, Outcome Report
A5: Venue Session | B5: (not shown) | C5: A server-side record that a given user is present at a given Event, with a TTL. Replaces continuous proximity scanning entirely. | D5: NOT a location record. No latitude/longitude is ever stored. It is a room membership, not a position. | E5: Backend only | F5: Live Room, Session Identifier, Go Live
A6: Live Room | B6: The room | C6: The set of users who currently have an active Venue Session at one Event and have gone Live. Matching only ever searches inside a Live Room. | D6: Not a chat room. Not a public attendee list - you never browse it. | E6: Live tab | F6: Venue Session, Live Count, Match
A7: Venue QR | B7: Ol-ga code | C7: BACKUP PATH. A printed QR at badge pickup, on tables, or on a co-working sign that creates a Venue Session when scanned. | D7: Not the primary entry route any more - geofence is. It remains the only route that works with location permission denied, and the only route at a co-working sign. | E7: Physical venue; QR scanner screen | F7: Venue Session, Geofence Check
A8: Geofence Check | B8: (not shown) | C8: PRIMARY PATH. A single coarse location check, once, in the foreground on app open, placing the user in the Live Room with no scanning. | D8: NOT background location. NOT continuous. NOT a position that is stored. It happens once, in the foreground, and produces a room membership. | E8: Backend + one permission prompt | F8: Venue QR, Venue Session
A9: Go Live | B9: Go Live | C9: The explicit user action that makes them visible to matching, for a duration they choose - the story's 'go live for the hour before my meeting'. | D9: Not automatic, not passive presence, and not open-ended. Being in the venue does not make you visible, and going Live does not keep you visible indefinitely. | E9: Live tab | F9: Go Offline, Live Count
A10: Live | B10: Live | C10: The state of a user who has gone Live and whose Venue Session has not expired. | D10: Not 'online' in a messaging sense. It is scoped to one Event and expires. | E10: Live tab; Live Count | F10: Go Live
A11: Go Offline | B11: Go Offline | C11: The user action that ends visibility immediately. Presence disappears within 5 seconds. | D11: Not logging out. The account, Ledger and Connections all remain. | E11: Live tab | F11: Go Live, Venue Session
A12: Live Count | B12: 'N people live right now' | C12: The number of users currently Live in this Live Room. Shown honestly, including when it is low. | D12: Not attendance. Not registrations. Only people who actively went Live. | E12: Live tab | F12: Live Room
... A49: Usefulness Label | B49: Was it useful? | C49: The second outcome question, asked only when a user answered yes to having met. One tap. | D49: Not a rating of the person, never shown to the other party, and not the same fact as having met. 'Nine of fourteen were useful' is only possible because this is separate. | E49: Outcome prompt | F49: Outcome Label, Encounter Graph

Sheet Feature Register
A1: ID | B1: Epic | C1: Feature | D1: User-facing name | E1: What it does | F1: User value | G1: Type | H1: Priority | I1: Milestone | J1: Effort | K1: Owner | L1: Depends on | M1: Acceptance criteria | N1: States required | O1: Analytics events | P1: Risk / note
A2: F-001 | B2: E6 Identity & Onboarding | C2: Phone / email OTP sign-in | D2: Sign in | E2: One-time code to phone or email. No password, no social login required. | F2: Gets a stranger in without a barrier, in under 30 seconds. | G2: Table stakes | H2: P0 | I2: M1 | J2: M | K2: SD | L2: Managed backend auth | M2: New user receives and enters a code and reaches the profile screen; both SMS and email paths work; tested on Maxis, Celcom, Digi and U Mobile. | N2: Default; code sent; invalid code; expired code; rate limited; no network | O2: signup_started, signup_completed | P2: SMS deliverability on Malaysian carriers is the risk. Keep email OTP first-class, not a fallback.
A3: F-002 | B3: E6 Identity & Onboarding | C3: Deep link entry from ticket email | D3: (invisible) | E3: A link in the Organiser's ticket confirmation opens the app - or the store, then the app - and lands the user directly on Intent capture for that Event. | F3: Removes every step between deciding to join and stating what you want. | G3: Differentiating | H3: P0 | I3: M1 | J3: M | K3: SD | L3: F-001; Organiser email platform | M3: Link from a real confirmation email opens the installed app on Intent capture with the correct Event pre-bound; if not installed, it routes via the store and preserves the Event on first open. | N3: Default; app not installed; wrong/expired Event; already completed | O3: install (with install_source) | P3: Highest-leverage feature in the whole register. Blocked on the Organiser registration agreement, not on code.
A4: F-003 | B4: E6 Identity & Onboarding | C4: Minimal profile | D4: Your profile | E4: STORY-ALIGNED: name and role. That is all. No photo, no company at sign-up. | F4: The story's onboarding is 40 seconds - 'verify your number, type your role, and write one line'. Every extra field is measured against that. | G4: Table stakes | H4: P0 | I4: M1 | J4: XS | K4: JA | L4: F-001 | M4: Profile completes in under 20 seconds. Two fields only. A third field may not be added without an equal removal, in writing. | N4: Default; incomplete; saving; save failed | O4: profile_completed | P4: CHANGED to match the story brief. Company was removed - the hard rules layer now derives seniority context from role text and event type instead.
A5: F-004 | B5: E6 Identity & Onboarding | C5: LinkedIn profile prefill | D5: Import from LinkedIn | E5: Optional one-tap prefill of name and role. Never a sign-in path. | F5: Saves typing for the users most likely to have a complete profile. | G5: Table stakes | H5: P2 | I5: M1 | J5: S | K5: JA | L5: F-003 | M5: Prefill populates both fields and the user can edit each one before saving. App is fully usable without it. | N5: Default; auth failed; declined; partial data | O5: profile_prefill_used | P5: Cut first if behind. With profile down to two fields, this saves very little - reconsider whether it is worth building at all.
A6: F-008 | B6: E6 Identity & Onboarding | C6: Deferred photo prompt | D6: Add a photo | E6: Asks for a profile photo AFTER the first Reveal, not at sign-up, framed as helping people find you. | F6: Keeps onboarding at 40 seconds while still getting photos onto the profiles that matter - the ones people are trying to find in a ballroom. | G6: Table stakes | H6: P1 | I6: M3 | J6: S | K6: JA | L6: F-003, F-036 | M6: Prompt never appears during onboarding. Reveal renders correctly with an initials placeholder when no photo exists. | N6: No photo (initials); prompted; uploading; upload failed | O6: photo_added | P6: Consequence of the 40-second onboarding decision. Without this, most Reveals will show initials at Event 1 - make sure the placeholder is designed, not default.
A7: F-005 | B7: E6 Identity & Onboarding | C7: Push permission request | D7: (system prompt) | E7: Asks for notification permission immediately AFTER the first Match Set is served, never at install. | F7: Asked at the moment of proven value, so the grant rate is far higher. | G7: Operational | H7: P0 | I7: M2 | J7: XS | K7: JA | L7: F-015 | M7: Prompt does not appear before the first Match Set. Grant rate measured. App degrades gracefully if denied. | N7: Granted; denied; previously denied (deep link to settings) | O7: push_permission_prompted, push_permission_result | P7: The Outcome loop depends on this. Asking at install would quietly halve gate metric 2.
A8: F-006 | B8: E6 Identity & Onboarding | C8: Self-serve account deletion | D8: Delete my account | E8: Deletes the account and all personal data from a single screen, with confirmation. | F8: Trust, and the PDPA erasure right. | G8: Table stakes | H8: P0 | I8: M1 | J8: S | K8: SD | L8: F-001 | M8: Deletion completes within the stated window and is verified by an actual test, not an assumption. Encounter rows are anonymised, not orphaned. | N8: Confirm; processing; done; failed | O8: account_deleted | P8: Build in M1 while there are three tables. Expensive against fifteen.
A9: F-007 | B9: E6 Identity & Onboarding | C9: Self-serve data export | D9: Download my data | E9: Exports the user's profile, intents, connections and outcomes in a readable format. | F9: PDPA portability right. | G9: Table stakes | H9: P0 | I9: M1 | J9: S | K9: SD | L9: F-001 | M9: Export delivered to the user and contains every category named in the privacy notice. | N9: Request; preparing; ready; failed | O9: data_export_requested | P9: Same reasoning as F-006 - trivial now, expensive later.
A10: F-010 | B10: E2 Intent & Matching | C10: Intent capture | D10: What are you hoping to get out of the evening? | E10: STORY-ALIGNED: ONE free-text line. No structured selects. Captured in the ticket confirmation, before arrival. | F10: Matching quality is entirely downstream of this one sentence. The story's example - 'looking for a distribution partner for our fintech product in Indonesia' - is the quality bar. | G10: Differentiating | H10: P0 | I10: M1 | J10: S | K10: JA | L10: F-001, F-002 | M10: Whole onboarding including this line completes in under 40 seconds median. One required field. Bound to one Go Live session, not permanently to the user. | N10: Default; empty; too short; typing; saving; saved; save failed; offline | O10: intent_submitted | P10: CHANGED: the two structured selects from the build plan are removed to match the story. The prompt wording is now the ONLY input to matching and is the highest-leverage copy decision in the product. Show the story's example verbatim as placeholder text.
A11: F-011 | B11: E2 Intent & Matching | C11: Per-session intent | D11: Change what you're here for | E11: STORY-ALIGNED: Intent belongs to a Go Live session, not to the Event or the profile. The story's user goes live at a co-working space 'with a different intent: hiring a senior backend engineer'. | F11: What you want at an awards night and what you want on a Tuesday morning are different things. Binding intent to the person would make matching wrong most of the time. | G11: Differentiating | H11: P0 | I11: M2 | J11: S | K11: JA | L11: F-010 | M11: Going Live in a new room pre-fills the previous Intent but explicitly prompts to rewrite it. Editing invalidates the cached Match Set. | N11: Default; prefilled from last session; editing; regenerating | O11: intent_edited | P11: UPGRADED P1 to P0 after the story review. This is a data-model decision, not a UI one - settle it at M0, not in Week 6.
A12: F-012 | B12: E2 Intent & Matching | C12: Intent embedding generation | D12: (invisible) | E12: Sends the Intent Line to a hosted embedding API and stores the vector against the Event. | F12: Makes semantic matching possible at all. | G12: Differentiating | H12: P0 | I12: M2 | J12: M | K12: SD | L12: F-010; embedding vendor | M12: Embedding generated on submit and on edit. Two providers configured behind one interface. Failure is retried and surfaced as a degraded state, never as a blank screen. | N12: Success; vendor error; retry; timeout | O12: embedding_generated | P12: Vendor-abstracted from day one so an outage on Event day is a config change.
... A80: F-106 | B80: E10 Outcome Report | C80: Report generation | D80: Event report | E80: Produces the delivered document: live users over time, matches, accepted connections, Confirmed Meetings, intent themes, sponsor-attributable stats. | F80: Converts one in-kind Event into a priced pipeline. This is the sellable object. | G80: Differentiating | H80: P1 | I80: M5 | J80: S | K80: F | L80: F-105 | M80: Delivered to the Organiser within 5 working days of Event end. Reviewed by the founder before it leaves the building. | N80: - | O80: - | P80: Publish it internally even when the numbers are unflattering. A report you would only send when the numbers are good is not a product.

Sheet Phase 2 Register
A1: ID | B1: Theme | C1: Feature | D1: What it does | E1: Why it matters | F1: ENTRY CONDITION - do not start before | G1: Effort | H1: Depends on | I1: Key risk
A2: P2-01 | B2: Ambient density (co-working) | C2: Permanent venue room | D2: A Live Room that persists indefinitely for a fixed venue - a co-working floor - rather than for a time-boxed Event. | E2: The bridge from episodic to ambient usage. The liquidity thesis rests entirely on this working. | F2: Cohort-1 week-4 off-event retention at or above 8%. Below that, fix the core loop instead of adding a venue type. | G2: M | H2: F-070, F-025 | I2: A 60-member floor produces worse density than an 800-person hall, and a weak result reads as a verdict on the whole thesis when it is really a verdict on n=60.
A3: P2-02 | B3: Ambient density (co-working) | C3: Badge-in entry integration | D3: Creates a Venue Session automatically when a member badges into the venue, via the operator's access system. | E3: Removes the only friction that matters in a daily-use context - nobody scans a QR every morning. | F3: P2-01 live, and a co-working operator willing to expose their access API. | G3: M | H3: P2-01 | I3: Third-party access-control integration is slow and operator-specific. Do not promise it before one operator has agreed in writing.
A4: P2-03 | B4: Ambient density (co-working) | C4: Fixed BLE beacon region monitoring | D4: A fixed beacon at a known venue with iOS/Android region monitoring, giving passive room entry without continuous scanning. | E4: This is where proximity radio legitimately returns - a tractable problem, unlike a peer-to-peer mesh. | F4: P2-01 and P2-02 both live. Never as an MVP substitute for the server-side Venue Session. | G4: L | H4: P2-01 | I4: Reintroduces battery, permission and store-review questions the MVP deliberately avoided. Scope it as one venue, one beacon, one test.
A5: P2-04 | B5: Ambient density (co-working) | C5: Weekday availability schedule | D5: Lets a member declare recurring windows when they are open to being matched. | E5: Converts Go Live from a per-visit action into a standing preference, which is what daily habit requires. | F5: P2-01 live and weekday go-live rate measured for at least 4 weeks. | G5: M | H5: P2-01 | I5: Risks becoming passive presence by the back door. The user must still be able to see and revoke it in one tap.
A6: P2-05 | B6: Ambient density (co-working) | C6: Floor-level live count | D6: Ambient count of who is available on a floor or in a building right now. | E6: The 'glance at the signal' behaviour the product narrative is built on. | F6: P2-01 live. | G6: S | H6: P2-01 | I6: At low density this number is discouraging rather than motivating. Consider a threshold below which it is not shown.
A7: P2-06 | B7: Organiser console | C7: Self-serve event creation | D7: Lets an Organiser create and configure their own Event without your team. | E7: The step that turns a services business into a product business. | F7: FIVE paying Organisers. Until then, concierge delivery teaches you what the console should be. | G7: M | H7: F-070 | I7: 6-8 developer-weeks in total across P2-06 to P2-09. In the MVP window this would come directly out of the Ledger and the Outcome Prompt.
A8: P2-07 | B8: Organiser console | C8: Attendee list upload | D8: Self-serve upload and validation of the expected attendee list. | E8: Removes the most common manual step in running an Event. | F8: P2-06 live. | G8: S | H8: F-071, P2-06 | I8: Attendee lists are personal data supplied by a third party. Get the processor/controller relationship documented before building this.
A9: P2-08 | B9: Organiser console | C9: Organiser live dashboard | D9: Read-only live view of their own Event: live count, matches, connections. | E9: Organisers want to watch it happen, and watching it happen is what they tell their sponsors about. | F9: P2-06 live. | G9: M | H9: F-073, P2-06 | I9: Must be strictly aggregate. An Organiser must never see who connected with whom.
A10: P2-09 | B10: Organiser console | C10: Self-serve Outcome Report | D10: Generates and downloads the Outcome Report without your team. | E10: Removes the 5-working-day manual step and makes the report a product feature rather than a service. | F10: Three Events delivered manually, so the format has stopped changing. | G10: M | H10: F-106, P2-06 | I10: Do not automate a document whose contents are still being learned. Automate it once two Organisers in a row asked for nothing new.
A11: P2-10 | B11: Organiser console | C11: Sponsor attribution | D11: Attributes matches and Confirmed Meetings to a sponsor's stand, session or track. | E11: Sponsorship is where Organiser budget actually sits. This is what makes the report worth a five-figure fee. | F11: One Organiser has asked for it in writing during a priced conversation. | G11: M | H11: F-105 | I11: Attractive, and it is the feature most likely to be requested before it is validated. Wait for the written ask.
A12: P2-11 | B12: Graph & intelligence | C12: Cross-event network surface | D12: Shows a user their accumulated network across Events, and where the overlaps are. | E12: Makes the Ledger feel like a compounding asset rather than a list. | F12: Two Events delivered, and cross-event Ledger continuity (F-049) proven. | G12: M | H12: F-049 | I12: This is the closest thing to a feed in the roadmap. Keep it a view of what the user earned, never a discovery surface.
... A19: P2-18 | B19: Platform | C19: Intent templates by event type | D19: Pre-written Intent prompts tuned to the kind of Event - awards night, trade show, conference. | E19: The Intent Line wording is the highest-leverage copy in the product; different Event types need different prompts. | F19: Two Events delivered with the same prompt, so you have a baseline to vary against. | G19: S | H19: F-010 | I19: Cheap and high value. This is the most likely Phase 2 item to earn its place early.

Sheet User Journey
A1: Step | B1: Stage | C1: Actor | D1: Screen | E1: What the user sees | F1: What the user does | G1: System response | H1: Terminology introduced | I1: Entry condition | J1: Exit condition | K1: Edge cases & failure | L1: Notification | M1: Data captured | N1: Event fired | O1: Feature IDs
A2: 1 | B2: A. Before the event | C2: Attendee | D2: (external) | E2: The Organiser's normal ticket purchase or registration page. | F2: Registers for the event as they always would. | G2: Registration recorded by the Organiser. Ol-ga is not involved yet. | H2: Event, Organiser | I2: Person decides to attend. | J2: Registration confirmed. | K2: None that Ol-ga owns. | L2: - | M2: (none - external system) | N2: - | O2: -
A3: 2 | B3: A. Before the event | C3: Attendee | D3: (email) | E3: The ticket confirmation email, which now carries an Ol-ga section: what it is, and a link. | F3: Reads it, or does not. | G3: Nothing yet. The link carries the Event identifier. | H3: Ol-ga | I3: Registration confirmed. | J3: Email received. | K3: Email lands in spam; Organiser sends late; user registered before Ol-ga was added. | L3: Email (Organiser's) | M3: - | N3: - | O3: F-002
A4: 3 | B4: A. Before the event | C4: Attendee | D4: App store / app | E4: Either the app store listing, or the app opening directly if already installed. | F4: Taps the link in the email. | G4: Deep link resolves. If not installed, routes via the store and preserves the Event for first open. | H4: - | I4: Email received. | J4: App installed and opened. | K4: Store link fails on an unsupported OS version; user opens on desktop; link opened twice. | L4: - | M4: install_source = ticket_email | N4: install | O4: F-002, F-083, F-101
A5: 4 | B5: A. Before the event | C5: Attendee | D5: Sign in | E5: A single field: phone number or email. No password. | F5: Enters phone or email, then the code they receive. | G5: One-time code sent and verified. Account created. | H5: - | I5: App opened. | J5: Signed in. | K5: Code not delivered (carrier); code expired; wrong code three times; no network. | L5: SMS or email (OTP) | M5: Contact identifier, timestamp | N5: signup_started, signup_completed | O5: F-001
A6: 5 | B6: A. Before the event | C6: Attendee | D6: Consent | E6: Plain-language consent screen written by counsel. | F6: Reads and accepts, or declines and leaves. | G6: Consent recorded with version and timestamp. | H6: - | I6: Signed in. | J6: Consent recorded. | K6: User declines - they must be able to leave cleanly with nothing stored. | L6: - | M6: Consent version, timestamp | N6: consent_recorded | O6: F-086
A7: 6 | B7: A. Before the event | C7: Attendee | D7: Profile | E7: Name and role. Two fields. | F7: Types their role. | G7: Profile saved. This is everything a Reveal will show, plus a photo later. | H7: - | I7: Consent recorded. | J7: Profile complete. | K7: LinkedIn prefill returns partial data; user has no clear job title. | L7: - | M7: Name, photo, role, company | N7: profile_completed, profile_prefill_used | O7: F-003, F-004
A8: 7 | B8: A. Before the event | C8: Attendee | D8: Intent capture | E8: One text box: 'What are you hoping to get out of the evening?' with the story's example as placeholder. | F8: Writes one line - the story's user writes 'looking for a distribution partner for our fintech product in Indonesia'. | G8: Intent stored against this session and sent for embedding. | H8: Intent, Intent Line | I8: Profile complete. | J8: Intent submitted. | K8: User writes one vague word; user writes an essay; embedding vendor is down (retry, never block). | L8: - | M8: Intent text, session id | N8: intent_submitted, embedding_generated | O8: F-010, F-012, F-090
A9: 8 | B9: A. Before the event | C9: Attendee | D9: Ready confirmation | E9: 'You're set. Just open Ol-ga when you arrive and tap Go Live.' | F9: Reads and closes the app. | G9: Nothing further until arrival. No presence exists yet. | H9: Go Live | I9: Intent submitted. | J9: User closes the app. | K9: User expects matches now. The copy must set the expectation - and must NOT tell them to hunt for a QR code, because geofence is the primary path. | L9: - | M9: - | N9: - | O9: F-010
A10: 9 | B10: A. Before the event | C10: System | D10: (push) | E10: A reminder on the morning of the event: 'Scan the Ol-ga code at registration.' | F10: Nothing. | G10: Push sent only to users who completed Intent. | H10: - | I10: Event day arrives. | J10: Push delivered. | K10: Push permission not yet granted (it is requested later, so most users will not receive this) - the QR at the venue is the real safety net. | L10: Push | M10: - | N10: push_sent | O10: F-058
A11: 10 | B11: B. At the venue | C11: Attendee | D11: Live tab | E11: The app opens and they are already in the room: '147 people live right now'. | F11: Opens the app. That is all. | G11: One coarse foreground location check places them in the Live Room. No scanning, no camera. | H11: Live Room, Venue Session | I11: Physically at the venue. | J11: Venue Session created. | K11: Location permission denied - route to the QR path in one tap; out of geofence range; no network at the door. | L11: - | M11: Event id, session identifier, timestamp | N11: room_entered (method=geofence) | O11: F-026, F-030, F-025
A12: 11 | B12: B. At the venue | C12: Attendee | D12: Live tab | E12: The live count, and a Go Live control asking two things: how long, and where in the venue you are. | F12: Picks 'for the hour' and taps 'north bar'. | G12: Availability window and self-declared zone are attached to the session. Zone is optional and skippable. | H12: Availability Window, Venue Zone | I12: Venue Session created. | J12: User sees the room. | K12: User skips the zone - every Match Card must render correctly without it. | L12: - | M12: Window minutes, declared zone | N12: zone_declared | O12: F-027, F-021, F-028
A13: 12 | B13: B. At the venue | C13: Attendee | D13: Live tab | E13: The Go Live control, and a one-line reminder of what going Live means. | F13: Taps Go Live. | G13: User becomes visible to matching. Match generation starts immediately. | H13: Go Live, Live | I13: In the Live Room. | J13: User is Live. | K13: User expects to be found without going Live - this must be impossible and the copy must say so. | L13: - | M13: Session state, timestamp | N13: went_live | O13: F-027
... A35: 34 | B35: D. Away from the venue | C35: Attendee | D35: Live tab (next event) | E35: The same Go Live flow, at a different event, with the Ledger intact underneath. | F35: Scans a new venue code months later. | G35: New Venue Session, new Match Set, new Intent. The Ledger accumulates across events. | H35: Cross-event continuity | I35: Attending a second event. | J35: Loop repeats. | K35: Their old Intent is pre-filled and no longer relevant - prompt them to rewrite it. | L35: - | M35: New Event id | N35: room_entered, intent_submitted | O35: F-049, F-011

Sheet Screens & States
A1: Screen ID | B1: Screen | C1: Purpose | D1: State | E1: Trigger | F1: What is shown | G1: Copy guidance | H1: Primary action | I1: Feature IDs
A2: S-01 | B2: Sign in | C2: Get a stranger in without a barrier | D2: Default | E2: App opened, not signed in | F2: One field: phone or email | G2: Say what happens next: 'We'll text you a code' | H2: Send code | I2: F-001
A3: S-01 | B3: Sign in | D3: Code sent | E3: Identifier submitted | F3: Code entry, resend timer | G3: Name the destination: 'Code sent to +60...' | H3: Verify | I3: F-001
A4: S-01 | B4: Sign in | D4: Invalid / expired code | E4: Wrong or stale code | F4: Inline error on the field | G4: Say what to do, not what went wrong: 'That code has expired - resend' | H4: Resend | I4: F-001
A5: S-01 | B5: Sign in | D5: No network | E5: Request failed | F5: Retry affordance, entered value preserved | G5: Never lose what they typed | H5: Retry | I5: F-001, F-094
A6: S-02 | B6: Consent | C6: Record consent lawfully and plainly | D6: Default | E6: First sign-in | F6: Counsel-approved plain-language consent | G6: Plain language, no dark patterns, decline is a real option | H6: Accept | I6: F-086
A7: S-03 | B7: Profile | C7: Enough for a Reveal to mean something | D7: Default | E7: Consent recorded | F7: Name and role. TWO fields. | G7: Story target is 40 seconds for the whole onboarding. Say why role exists: 'this is what someone sees when you both accept' | H7: Save | I7: F-003
A8: S-03 | B8: Profile | D8: Prefill offered | E8: LinkedIn available | F8: Same fields, pre-populated, all editable | G8: Make it clear they can change everything | H8: Save | I8: F-004
A9: S-03 | B9: Profile | D9: Saving / save failed | E9: Save tapped | F9: Progress, or retry with values preserved | G9: Never lose the photo upload on a slow connection | H9: Retry | I9: F-003, F-094
A10: S-04 | B10: Intent capture | C10: The highest-leverage screen in the product | D10: Default | E10: Profile complete | F10: ONE text box. No dropdowns. | G10: Use the story's line as placeholder: 'looking for a distribution partner for our fintech product in Indonesia'. The prompt wording matters more than any other copy in the product. | H10: Submit | I10: F-010
A11: S-04 | B11: Intent capture | D11: Empty / too short | E11: Submit with no useful text | F11: Inline guidance with a worked example | G11: Show a good example, do not scold | H11: Submit | I11: F-010
A12: S-04 | B12: Intent capture | D12: Editing / new session | E12: Go Live in a new room | F12: Previous intent pre-filled, explicitly prompting a rewrite | G12: Story: a different room means a different intent. Prompt the rewrite, do not assume it carries over. | H12: Update | I12: F-011
A13: S-04 | B13: Intent capture | D13: Offline | E13: No network on submit | F13: Queued state, visibly saved locally | G13: Reassure that it is saved and will send | H13: - | I13: F-010, F-094
A14: S-05 | B14: Ready confirmation | C14: Set the expectation for the venue | D14: Default | E14: Intent submitted | F14: What happens on arrival: open the app and tap Go Live | G14: Do NOT tell them to hunt for a QR code - geofence is the primary path | H14: Done | I14: F-010, F-026
A15: S-06 | B15: Ledger (home) | C15: The reason to open the app on a Tuesday | D15: Empty | E15: No connections yet | F15: An explanation of what will appear here after their first event | G15: Not a failure state. This is a promise, not an apology. | H15: Go to Live | I15: F-045
A16: S-06 | B16: Ledger (home) | D16: Populated | E16: One or more connections | F16: Connections newest first, with event, date and decay marker | G16: Lead with the person and the reason, not the date | H16: Open connection | I16: F-045, F-047
A17: S-06 | B17: Ledger (home) | D17: Loading | E17: App opened | F17: Skeleton, not a spinner over a blank screen | G17: - | H17: - | I17: F-045
A18: S-06 | B18: Ledger (home) | D18: Offline (cached) | E18: No network | F18: Full ledger from cache, with a quiet offline marker | G18: Do not block reading. Reading works offline by design. | H18: - | I18: F-048
A19: S-07 | B19: Live tab | C19: Enter a room and become visible | D19: No live room | E19: Off-event, no venue session | F19: 'No live room right now' plus known upcoming events | G19: MOST-SEEN SCREEN BETWEEN EVENTS. Give it real design attention. | H19: Scan a code | I19: F-096
A20: S-07 | B20: Live tab | D20: In room, not live | E20: Geofence or QR placed them in the room | F20: Live count, a Go Live control, a duration picker and an optional zone picker | G20: Say plainly that nobody can see them until they tap Go Live | H20: Go Live | I20: F-026, F-027, F-021, F-028
A21: S-07 | B21: Live tab | D21: Going live | E21: Go Live tapped | F21: Brief generating state | G21: Under two seconds. Do not narrate. | H21: - | I21: F-013, F-082
A22: S-07 | B22: Live tab | D22: Live, matches served | E22: Match set ready | F22: Three match cards | G22: - | H22: Open a card | I22: F-015
A23: S-07 | B23: Live tab | D23: Live, low density | E23: Fewer than four candidates | F23: One or two cards, plus an honest note about room size | G23: 'Only 6 people are live right now' - honest, not apologetic | H23: - | I23: F-015, F-028
A24: S-07 | B24: Live tab | D24: Live, no candidates | E24: Nobody matchable | F24: Honest empty state and what to do | G24: Tell them to check back - do not fabricate a match | H24: - | I24: F-015
A25: S-07 | B25: Live tab | D25: Degraded (polling) | E25: Realtime unavailable | F25: Identical to normal; count updates more slowly | G25: Do not tell the user. It should be invisible. | H25: - | I25: F-093
A26: S-07 | B26: Live tab | D26: Session expired | E26: TTL elapsed | F26: Clear notice that they are no longer live, and how to return | G26: Never disappear silently - that reads as a bug | H26: Go Live again | I26: F-029
A27: S-08 | B27: QR scanner | C27: Enter a live room | D27: Default | E27: Scan tapped | F27: Camera view with a framing guide | G27: - | H27: - | I27: F-025
A28: S-08 | B28: QR scanner | D28: Camera denied | E28: Permission refused | F28: Explanation and a route to settings; offer the geofence path | G28: Do not dead-end. There is a second way in. | H28: Open settings | I28: F-025, F-026
A29: S-08 | B29: QR scanner | D29: Invalid / expired code | E29: Bad scan | F29: Clear, non-technical error | G29: 'That code isn't for an event running now' | H29: Try again | I29: F-025
A30: S-09 | B30: Match card | C30: Turn a name into an approach | D30: Default | E30: Match set served | F30: Explanation dominant, then role, then zone if declared | G30: Story shape: 'Regional director, payments. Also live, near the north bar.' The explanation is the product - give it the space. | H30: Connect | I30: F-016, F-021
A31: S-09 | B31: Match card | D31: Fallback explanation | E31: LLM failed or output rejected | F31: Rule-based sentence in the same treatment | G31: Must be indistinguishable in tone from a generated one | H31: Connect | I31: F-019
A32: S-09 | B32: Match card | D32: Request sent | E32: Connect tapped | F32: Neutral sent state | G32: MUST stay neutral forever. Never resolves into a visible rejection. | H32: - | I32: F-035, F-037
A33: S-09 | B33: Match card | D33: Rate limited | E33: Too many requests | F33: Friendly cap message | G33: Do not shame the user | H33: - | I33: F-039
A34: S-10 | B34: Incoming request | C34: Decide without seeing who | D34: Default | E34: Request received | F34: The requester's explanation and zone, WITHOUT their identity | G34: Story: 'she accepts in ninety seconds because she can see your reason too'. Make clear a decline is never seen by them. | H34: Accept | I34: F-036, F-037, F-021
A35: S-11 | B35: Reveal | C35: The payoff | D35: Default | E35: Mutual accept | F35: Name, photo, role, company, and a coarse venue cue | G35: This is the moment. Let it land - do not clutter it. | H35: Find them | I35: F-036
A36: S-12 | B36: Connection detail | C36: Remember who and why, months later | D36: Default | E36: Opened from ledger | F36: Person, event, date, THEIR INTENT IN THEIR OWN WORDS, the explanation, and what you owe them | G36: The own-words intent and the commitment line are what make this a memory rather than a contact card | H36: Mark commitment done | I36: F-046, F-050
A37: S-12 | B37: Connection detail | D37: Other user deleted | E37: Counterparty deleted account | F37: Respectful tombstone retaining the event and explanation | G37: A tombstone, not an error | H37: - | I37: F-046, F-006
A38: S-13 | B38: Outcome prompt | C38: Gate metric 2 | D38: Default (batched) | E38: Event ended + 3h | F38: 'You connected with three people tonight' then each in turn: did you meet? | G38: One tap per connection. Nothing else on the screen. | H38: Yes / No / Not yet | I38: F-052
A39: S-13 | B39: Outcome prompt | D39: In-app fallback | E39: Push denied | F39: The same batched sequence, on next open | G39: Identical wording to the push version | H39: Yes / No / Not yet | I39: F-055
A40: S-14 | B40: You (settings) | C40: Control and compliance | D40: Default | E40: Tab opened | F40: Profile, intent, notifications, privacy, export, delete | G40: Export and delete must be findable, not buried | H40: - | I40: F-062, F-087
...

Sheet Notifications
A1: ID | B1: Trigger | C1: Channel | D1: Timing | E1: Title | F1: Body | G1: Deep link to | H1: Opt-out behaviour | I1: Guardrail / caution | J1: Feature ID
A2: N-01 | B2: Event morning reminder | C2: Push | D2: Event day, 08:00 local | E2: Ol-ga is live at [Event] today | F2: Scan the Ol-ga code at registration to see who's in the room. | G2: Live tab | H2: Suppressed if event reminders are off | I2: Most users will not have granted push yet - the venue QR is the real safety net | J2: F-058
A3: N-02 | B3: Match set ready | C3: Push | D3: Immediately after Go Live | E3: Your three matches are ready | F3: Three people worth crossing the room for. | G3: Live tab | H3: Suppressed if match alerts are off | I3: Only ever sent while the user is Live. Never after they go offline. | J3: F-058
A4: N-03 | B4: Connect request received | C4: Push | D4: Within seconds of request | E4: Someone wants to connect | F4: They've explained why. Take a look before they move on. | G4: Incoming request | H4: Suppressed if request alerts are off | I4: Latency matters more here than anywhere. A request seen after the event is worthless. | J4: F-059
A5: N-04 | B5: Request accepted | C5: Push | D5: Within seconds of mutual accept | E5: You're connected | F5: Go and find them - here's where they are. | G5: Reveal | H5: Suppressed if request alerts are off | I5: NEVER send anything on decline. Same invariant as silent decline. | J5: F-060
A6: N-05 | B6: Outcome prompt | C6: Push | D6: Within 3 hours of event end | E6: You connected with three people tonight | F6: Did you actually meet? Three taps. | G6: Outcome prompt | H6: Suppressed if outcome alerts are off - in-app fallback then carries it | I6: GATE METRIC 2. ONE notification for the whole event, not one per connection - batching is what makes 'three taps' possible. | J6: F-061
A7: N-06 | B7: Outcome second nudge | C7: Push | D7: 72 hours after N-05, non-responders only | E7: Still worth a minute | F7: You still have connections from [Event] to confirm. | G7: Outcome prompt | H7: Suppressed if outcome alerts are off | I7: EXACTLY ONE nudge. A second reads as harassment and drives opt-out. | J7: F-053
A8: N-07 | B8: Session expiring | C8: In-app only | D8: 15 minutes before TTL | E8: You're about to go offline | F8: Tap to stay live for the rest of the event. | G8: Live tab | H8: n/a - in-app | I8: Deliberately not a push. Do not notify someone who has left the venue. | J8: F-029
A9: N-08 | B9: Decay indicator | C9: In-app only (MVP) | D9: Passive, on ledger open | E9: (no notification) | F9: (visual marker only) | G9: Ledger | H9: n/a - in-app | I9: DO NOT make this a push in the MVP. The ledger now names quiet connections with elapsed days, which is already assertive. Watch opt-out and uninstall rate. | J9: F-047

Sheet Analytics Events
A1: Event name | B1: When it fires | C1: Key properties | D1: Funnel step | E1: Feeds which metric | F1: Frozen at | G1: Feature IDs
A2: install | B2: First app open | C2: install_source, platform, event_id | D2: 1. Acquisition | E2: Live rate; cold-start machine effectiveness | F2: M0 | G2: F-002, F-083
A3: signup_started | B3: Sign-in screen submitted | C3: method (phone/email) | D3: 2. Sign-in | E3: Onboarding funnel | F3: M0 | G3: F-001
A4: signup_completed | B4: OTP verified | C4: method, seconds_from_install | D4: 2. Sign-in | E4: Onboarding funnel | F4: M0 | G4: F-001
A5: consent_recorded | B5: Consent accepted | C5: consent_version | D5: 2. Sign-in | E5: Compliance evidence | F5: M0 | G5: F-086
A6: profile_completed | B6: Profile saved | C6: prefill_used, seconds | D6: 3. Profile | E6: Onboarding funnel; time-to-intent | F6: M0 | G6: F-003, F-004
A7: intent_submitted | B7: Intent saved | C7: char_count, session_id, seconds_from_install (NO select fields - removed to match the story) | D7: 4. Intent | E7: Intent completion rate; time-to-intent (target <90s) | F7: M0 | G7: F-010
A8: intent_edited | B8: Intent changed at venue | C8: event_id | D8: 4. Intent | E8: Whether the pre-arrival prompt is working | F8: M0 | G8: F-011
A9: embedding_generated | B9: Vector produced | C9: vendor, latency_ms, retry_count | D9: (technical) | E9: Vendor reliability | F9: M0 | G9: F-012
A10: room_entered | B10: Venue session created | C10: method (qr/geofence), event_id | D10: 5. Presence | E10: Live rate denominator; QR vs geofence split | F10: M0 | G10: F-025, F-026
A11: went_live | B11: Go Live tapped | C11: event_id, room_size, window_minutes, zone_declared | D11: 5. Presence | E11: LIVE RATE - target 25% of checked-in attendees at peak | F11: M0 | G11: F-027
A12: went_offline | B12: Go Offline tapped | C12: session_duration_s | D12: 5. Presence | E12: Session length distribution | F12: M0 | G12: F-027
... A42: photo_added | B42: Profile photo added after first reveal | C42: prompted | D42: 3. Profile | E42: Whether the deferred-photo decision costs anything | F42: M0 | G42: F-008

Sheet Event Ops Runbook
A1: Step | B1: When | C1: Who | D1: Action | E1: Tool or surface | F1: Output | G1: Notes
A2: 1 | B2: Event minus 6 weeks | C2: Founder | D2: Agree the registration-flow integration in writing: confirmation-email link, QR at badge pickup and tables, 30 seconds from the stage. | E2: Email / contract with a NAMED Organiser owner | F2: Written commitment | G2: Highest-ranked initiative in the whole roadmap, and it is not engineering work.
A3: 2 | B3: Event minus 5 weeks | C3: Founder | D3: Confirm event date, expected attendance and check-in process. | E3: Organiser conversation | F3: Confirmed numbers | G3: The live-rate denominator comes from check-in, not registrations.
A4: 3 | B4: Event minus 4 weeks | C4: Operator | D4: Create the Event in the admin panel with venue, window and configuration. | E4: Admin panel (F-070) | F4: Live Event record | G4: A non-developer must be able to do this unaided.
A5: 4 | B5: Event minus 4 weeks | C5: Operator | D5: Upload the expected attendee list. | E5: Admin panel (F-071) | F5: Seeded event | G5: Bad rows are reported, never silently dropped.
A6: 5 | B6: Event minus 4 weeks | C6: Operator | D6: Generate the venue QR and send it to print. | E6: Admin panel (F-072) | F6: Print-ready QR | G6: Test the PRINTED artefact at badge-pickup distance and lighting, not the screen.
A7: 6 | B7: Event minus 3 weeks | C7: Founder | D7: Approve confirmation-email copy with the Organiser and schedule the send. | E7: Organiser's email platform | F7: Scheduled email | G7: Must not send before both app stores have approved.
A8: 7 | B8: Event minus 2 weeks | C8: Founder | D8: Run the 30-person dry run on a production build. | E8: Any room, 30 real devices | F8: Findings log | G8: Worth more than another week of testing. The item most likely to quietly not happen.
A9: 8 | B9: Event minus 2 weeks | C9: Senior dev | D9: Exercise all four kill switches and one OTA update end to end. | E9: Admin panel + EAS | F9: Verified rollback paths | G9: An untested kill switch is a rumour.
A10: 9 | B10: Event minus 1 week | C10: Founder | D10: Confirm signage placement, stage script slot in the run sheet, and help-desk staffing. | E10: Organiser run sheet | F10: Signed-off run sheet | G10: Get the case-study publication permission in writing at the same time.
A11: 10 | B11: Event minus 7 days | C11: Organiser | D11: Send the confirmation email carrying the Ol-ga deep link. | E11: Organiser's email platform | F11: Installs begin | G11: Watch click-through. Below 15% by event minus 5 days, escalate.
A12: 11 | B12: Event day, setup | C12: Operator | D12: Verify QR codes are in place at badge pickup and on every table; verify the Event is live in the panel. | E12: Physical + admin panel | F12: Room ready | G12: Walk the floor. Do not assume placement.
A13: 12 | B13: Event day, opening | C13: Organiser | D13: 30 seconds from the stage. | E13: Stage | F13: Install spike | G13: Measurable via install_source. If it is skipped, you will see it in the data.
... A21: 20 | B21: Event end + 28 days | C21: Founder | D21: Read week-4 off-event retention on the M0 definitions and no others. | E21: Cohort dashboard (F-081) | F21: GATE METRIC 1 | G21: Report D60/D90 alongside, with the acquisition-context disclosure.

Sheet Not Building
A1: Item | B1: Why it's tempting | C1: Why not now | D1: Reconsider when
A2: In-app chat | B2: Every user will ask for it; every competitor has it | C2: It is the single feature that would stop people meeting in person. The absence of chat is the mechanism, not an omission. | D2: Never, in this product. If messaging is ever needed it belongs AFTER a confirmed meeting, not before.
A3: A feed or content surface | B3: It looks like engagement, and engagement charts go up | C3: Converts a utility into a time-sink and destroys the intent signal that makes matching work. | D3: No evidence this roadmap can produce would justify it.
A4: Continuous background proximity | B4: It is the 'real' version of the idea and it demos beautifully | C4: iOS background BLE limits, Android OEM battery behaviour, a 9-hour day, App Review risk, and standing PDPA/DPDP liability. Costs ~6 weeks and buys a rejection risk. | D4: Phase 2 co-working only, as FIXED BEACONS at a known venue with region monitoring (P2-03) - a tractable and genuinely different problem.
A5: Self-serve organiser console | B5: It is how this becomes a product business rather than a services one | C5: 6-8 developer-weeks that would come directly out of the Ledger and the Outcome Prompt. | D5: FIVE paying organisers. Until then, concierge delivery teaches you what the console should be. (P2-06 to P2-09)
A6: Consumer paid tier / in-app billing | B6: The stated business model is subscription | C6: Nothing to charge for before the gate metric, and the evidence caps consumer conversion at 2-4% of WAU. Building billing now buys a store-compliance surface and no revenue. | D6: Week-4 off-event retention at or above 8% across TWO cohorts.
A7: Recruiter / BD seats at $200/month | B7: It is the highest-value line in the model | C7: Prices above LinkedIn Sales Navigator Advanced and above Apollo's top tier. Only defensible if real-time presence intent demonstrably beats database intent. | D7: First encounter-graph analysis showing intro-to-meeting-to-outcome conversion. Then launch at $99-$149. (P2-15)
A8: India launch | B8: Large market; the original plan; DPDP timing looks manageable | C8: The India-first launch was dropped definitively. Two regimes, two acquisition motions and two organiser networks across three developers, before a single gate metric exists. | D8: Two Malaysian cohorts clearing the gate, plus a DPDP Consent-Manager-compatible consent flow already in place. (P2-16)
A9: Telco / OEM distribution | B9: It is the Series A moat story | C9: A Series A unlock, not a pre-seed one. The honest precedent is OEM pre-install and strategic-investor placement, not telco subscriber bundling - and a partner controlling the network layer can commoditise your feature. | D9: Post-Series-A, and only with the encounter graph as the retained asset rather than the proximity layer.
A10: Contact import / persistent social graph | B10: It would make the ledger look full on day one | C10: The encounter graph's value comes from being earned and outcome-labelled. Importing contacts fills it with exactly the edges that carry no signal. | D10: Not on this thesis.
A11: Web app, tablet, landscape, localisation | B11: Cheap-looking, frequently requested | C11: Each is a permanent maintenance tax on a three-person team, with zero evidence of demand. | D11: Real demand from a paying organiser, in writing. (P2-17)
A12: Company pages, groups, sponsor booths | B12: Organisers will ask for them | C12: This is the event-tech feature set - the thing Grip and Brella already do well and sell against you. | D12: Only if you deliberately choose the B2B default after the month-9 checkpoint. Then it becomes the roadmap.
... A15: Custom NLP or a trained model | B15: It sounds like the moat | C15: The moat is the outcome-labelled encounter graph, not the matching layer. Embeddings are rented commodity and always will be. | D15: Never in this horizon. Revisit only when the graph itself is large enough to train on.

Sheet Milestone Checklist
A1: Milestone | B1: Name | C1: Due | D1: Acceptance criterion | E1: Binary test | F1: Payment | G1: Owner
A2: M0 | B2: Foundations | C2: End W1 - Sun 13 Sep | D2: App installs on a real iPhone AND a real Android from CI | E2: Binary: install both, from CI, on physical devices | F2: 10% | G2: SD
A3: M0 | B3: Foundations | C3: End W1 - Sun 13 Sep | D3: Typed API contracts published and mocked | E3: Binary: a junior builds a screen against the mock with no backend | F3: 10% | G3: SD
A4: M0 | B4: Foundations | C4: End W1 - Sun 13 Sep | D4: Analytics taxonomy signed off by founder and senior developer | E4: Binary: signed document exists | F4: 10% | G4: F + SD
A5: M0 | B5: Foundations | C5: End W1 - Sun 13 Sep | D5: Off-event definition implemented server-side with a CI test that fails on change | E5: Binary: edit the definition, watch CI fail | F5: 10% | G5: SD
A6: M0 | B6: Foundations | C6: End W1 - Sun 13 Sep | D6: Privacy invariants reviewed against the data model - no lat/long column exists anywhere | E6: Binary: schema review signed | F6: 10% | G6: SD + F
A7: M0 | B7: Foundations | C7: End W1 - Sun 13 Sep | D7: Presence decision recorded in writing; final technical authority named | E7: Binary: memo circulated to all three developers | F7: 10% | G7: F
A8: M0 | B8: Foundations | C8: End W1 - Sun 13 Sep | D8: EAS Update configured; crash reporting live | E8: Binary: both wired in the first build | F8: 10% | G8: SD
A9: M1 | B9: Identity & intent | C9: End W3 - Sun 27 Sep | D9: New user signs in, completes profile and submits intent from a ticket-email link | E9: Binary: end-to-end on a real device from a real email | F9: 15% | G9: SD + JA
A10: M1 | B10: Identity & intent | C10: End W3 - Sun 27 Sep | D10: An event can be created and seeded from the admin panel by a non-developer | E10: Binary: founder does it unaided | F10: 15% | G10: JB
A11: M1 | B11: Identity & intent | C11: End W3 - Sun 27 Sep | D11: Data export and delete endpoints working from the user-facing screen | E11: Binary: delete an account, verify the data is gone | F11: 15% | G11: SD
